Workbook

Sheet Leia-me
A1: CRM em quadro · Contorno Estética
A2: Clínica fictícia criada para o IA Sem Segredo. Nomes e números são inventados.
A4: Para que serve | B4: Organizar cada cliente numa etapa do funil e mostrar, todo dia, quem precisa de retorno.
A5: Clientes | B5: A base do CRM. As 80 clientes da planilha antiga já estão aqui, cada uma na etapa certa. Uma linha = um cartão do quadro.
A6: Painel | B6: Os números para a Paula: quantas clientes em cada etapa, retornos atrasados, origem e propostas que viraram pacote.
A7: Etapas do funil | B7: As 8 colunas do quadro, quando o cartão entra em cada uma e quem move.
A8: Dados do cliente | B8: O que cada campo significa e como preencher.
A9: Regras de retorno | B9: Quando a Nina volta a falar com a cliente em cada situação.
A10: Regras da clínica | B10: As regras que ninguém quebra e o que o CRM faz para proteger cada uma.
A11: Quem usa | B11: O que Nina, Otávio, Camila e Paula fazem no CRM.
A12: Pontos a confirmar | B12: Regras sugeridas que a Paula ainda precisa aprovar.
A14: COMO USAR NO DIA A DIA
A15: 1. | B15: Abra a aba Clientes e filtre a coluna "Situação do retorno" por "Atrasado" e "Hoje". Essa é a lista de retornos do dia.
A16: 2. | B16: Depois de falar com a cliente, atualize "Último contato" com a data de hoje e, se for o caso, mude a "Etapa".
A17: 3. | B17: Se a cliente não respondeu, some 1 em "Tentativas sem resposta". Na 3ª, a planilha avisa para mover para Perdido.
A18: 4. | B18: Se ela respondeu, volte as tentativas para 0.
A20: O QUE PREENCHER | B20: Células com fundo amarelo-claro são para preencher. As colunas "Área", "Validade do pacote", "Próximo retorno" e "Situação do retorno" são calculadas sozinhas: não digite nelas.
A21: MENUS | B21: Etapa, Origem, Interesse, Etiqueta da proposta, Responsável e Motivo da perda têm uma setinha com as opções. Escolha uma opção da lista em vez de escrever.
A22: DATAS | B22: As datas da planilha antiga não tinham ano. Considerei 2026 em todas.
A23: A COMPLETAR | B23: Clientes sem origem ou sem interesse na planilha antiga aparecem como "A completar". A Nina completa na próxima conversa.
A24: DOMINGO | B24: Se o próximo retorno cair num domingo, a planilha passa para segunda. Feriados precisam ser ajustados à mão.

Sheet Painel
A1: Painel da Paula
A2: Atualiza sozinho a partir da aba Clientes.
A4: Clientes por etapa | B4: Quantidade | D4: Retornos | E4: Quantidade
A5: Novo contato | B5: =COUNTIF(Clientes!$G$2:$G$500,A5) -> 8 | D5: Atrasado | E5: =COUNTIF(Clientes!$R$2:$R$500,D5) -> 52
A6: Em conversa | B6: =COUNTIF(Clientes!$G$2:$G$500,A6) -> 28 | D6: Hoje | E6: =COUNTIF(Clientes!$R$2:$R$500,D6) -> 27
A7: Avaliação marcada | B7: =COUNTIF(Clientes!$G$2:$G$500,A7) -> 18 | D7: Mover para Perdido | E7: =COUNTIF(Clientes!$R$2:$R$500,D7) -> 0
A8: Proposta enviada | B8: =COUNTIF(Clientes!$G$2:$G$500,A8) -> 18 | D8: No prazo | E8: =COUNTIF(Clientes!$R$2:$R$500,D8) -> 1
A9: Fechou pacote | B9: =COUNTIF(Clientes!$G$2:$G$500,A9) -> 8
A10: Em tratamento | B10: =COUNTIF(Clientes!$G$2:$G$500,A10) -> 0
A11: Pós-venda | B11: =COUNTIF(Clientes!$G$2:$G$500,A11) -> 0 | D11: Origem das clientes | E11: Quantidade
A12: Perdido | B12: =COUNTIF(Clientes!$G$2:$G$500,A12) -> 0 | D12: Instagram | E12: =COUNTIF(Clientes!$C$2:$C$500,D12) -> 30
A13: Total | B13: =SUM(B5:B12) -> 80 | D13: Instagram (anúncio) | E13: =COUNTIF(Clientes!$C$2:$C$500,D13) -> 11
D14: Google | E14: =COUNTIF(Clientes!$C$2:$C$500,D14) -> 5
A15: Propostas que viraram pacote | D15: Indicação | E15: =COUNTIF(Clientes!$C$2:$C$500,D15) -> 26
A16: Fecharam (Fechou pacote + Em tratamento + Pós-venda) | B16: =B9+B10+B11 -> 8 | D16: Fachada | E16: =COUNTIF(Clientes!$C$2:$C$500,D16) -> 0
A17: Ainda com proposta em aberto | B17: =B8 -> 18 | D17: Outro | E17: =COUNTIF(Clientes!$C$2:$C$500,D17) -> 0
A18: Taxa de fechamento | B18: =IF(B16+B17=0,0,B16/(B16+B17)) -> 0.30769231 | D18: A completar | E18: =COUNTIF(Clientes!$C$2:$C$500,D18) -> 8
A19: Referência da clínica: 4 em cada 10 avaliações viram pacote (média dos últimos 6 meses, documento Quem Somos).
A20: Fecharam ÷ (fecharam + propostas em aberto). Não conta as perdidas, porque a planilha antiga não dizia em que etapa a cliente desistiu.

Sheet Clientes
A1: Nome | B1: Telefone / WhatsApp | C1: Origem | D1: Indicada por | E1: Interesse | F1: Área | G1: Etapa | H1: Etiqueta da proposta | I1: Responsável | J1: Último contato | K1: Tentativas sem resposta | L1: Data da avaliação | M1: Data da 1ª sessão | N1: Sessões contratadas | O1: Sessões feitas | P1: Validade do pacote | Q1: Próximo retorno | R1: Situação do retorno | S1: Preferências e cuidados | T1: Motivo da perda | U1: Observação | V1: Situação na planilha antiga | W1: Retorno (cálculo)
A2: Cliente 001 | B2: (15) 99999-3042 | C2: Indicação | E2: Criolipólise | F2: =IF(OR(E2="",E2="A completar",E2="Ainda não sabe"),"",IF(OR(E2="Limpeza de pele",E2="Peeling de diamante",E2="Microagulhamento"),"Rosto","Corpo")) -> Corpo | G2: Avaliação marcada | I2: Nina | J2: 46256 | K2: 0 | P2: =IF(M2="","",EDATE(M2,6)) | Q2: =IF(W2="","",IF(WEEKDAY(W2)=1,W2+1,W2)) -> 46309 | R2: =IF(Q2="","",IF(AND(N(K2)>=3,G2<>"Perdido"),"Mover para Perdido",IF(Q2<TODAY(),"Atrasado",IF(Q2=TODAY(),"Hoje","No prazo")))) -> Hoje | V2: marcou avaliação | W2: =IF(G2="","",IF(OR(G2="Novo contato",G2="Em conversa"),IF(J2="",TODAY(),J2+1),IF(G2="Avaliação marcada",IF(L2="",TODAY(),L2-1),IF(G2="Proposta enviada",IF(J2="",TODAY(),J2+2),IF(G2="Fechou pacote",IF(J2="",TODAY(),J2+7),IF(G2="Em tratamento",IF(M2="",TODAY(),IF(TODAY()<=M2+1,M2+1,EDATE(M2,6)-30)),IF(G2="Pós-venda",IF(J2="",TODAY(),J2+7),IF(G2="Perdido",IF(J2="",TODAY(),J2+60),"")))))))) -> 46309
A3: Cliente 002 | B3: (15) 99999-3504 | C3: Indicação | E3: Drenagem linfática | F3: =IF(OR(E3="",E3="A completar",E3="Ainda não sabe"),"",IF(OR(E3="Limpeza de pele",E3="Peeling de diamante",E3="Microagulhamento"),"Rosto","Corpo")) -> Corpo | G3: Em conversa | I3: Nina | K3: 1 | P3: =IF(M3="","",EDATE(M3,6)) | Q3: =IF(W3="","",IF(WEEKDAY(W3)=1,W3+1,W3)) -> 46309 | R3: =IF(Q3="","",IF(AND(N(K3)>=3,G3<>"Perdido"),"Mover para Perdido",IF(Q3<TODAY(),"Atrasado",IF(Q3=TODAY(),"Hoje","No prazo")))) -> Hoje | V3: sumiu | W3: =IF(G3="","",IF(OR(G3="Novo contato",G3="Em conversa"),IF(J3="",TODAY(),J3+1),IF(G3="Avaliação marcada",IF(L3="",TODAY(),L3-1),IF(G3="Proposta enviada",IF(J3="",TODAY(),J3+2),IF(G3="Fechou pacote",IF(J3="",TODAY(),J3+7),IF(G3="Em tratamento",IF(M3="",TODAY(),IF(TODAY()<=M3+1,M3+1,EDATE(M3,6)-30)),IF(G3="Pós-venda",IF(J3="",TODAY(),J3+7),IF(G3="Perdido",IF(J3="",TODAY(),J3+60),"")))))))) -> 46309
A4: Cliente 003 | B4: (15) 99999-4519 | C4: Instagram | E4: Limpeza de pele | F4: =IF(OR(E4="",E4="A completar",E4="Ainda não sabe"),"",IF(OR(E4="Limpeza de pele",E4="Peeling de diamante",E4="Microagulhamento"),"Rosto","Corpo")) -> Rosto | G4: Proposta enviada | I4: Nina | J4: 46300 | K4: 0 | P4: =IF(M4="","",EDATE(M4,6)) | Q4: =IF(W4="","",IF(WEEKDAY(W4)=1,W4+1,W4)) -> 46302 | R4: =IF(Q4="","",IF(AND(N(K4)>=3,G4<>"Perdido"),"Mover para Perdido",IF(Q4<TODAY(),"Atrasado",IF(Q4=TODAY(),"Hoje","No prazo")))) -> Atrasado | S4: Já fez em outra clínica | V4: fez avaliação | W4: =IF(G4="","",IF(OR(G4="Novo contato",G4="Em conversa"),IF(J4="",TODAY(),J4+1),IF(G4="Avaliação marcada",IF(L4="",TODAY(),L4-1),IF(G4="Proposta enviada",IF(J4="",TODAY(),J4+2),IF(G4="Fechou pacote",IF(J4="",TODAY(),J4+7),IF(G4="Em tratamento",IF(M4="",TODAY(),IF(TODAY()<=M4+1,M4+1,EDATE(M4,6)-30)),IF(G4="Pós-venda",IF(J4="",TODAY(),J4+7),IF(G4="Perdido",IF(J4="",TODAY(),J4+60),"")))))))) -> 46302
A5: Cliente 004 | B5: (15) 99999-4205 | C5: Google | E5: Depilação a laser | F5: =IF(OR(E5="",E5="A completar",E5="Ainda não sabe"),"",IF(OR(E5="Limpeza de pele",E5="Peeling de diamante",E5="Microagulhamento"),"Rosto","Corpo")) -> Corpo | G5: Em conversa | I5: Nina | J5: 46278 | K5: 1 | P5: =IF(M5="","",EDATE(M5,6)) | Q5: =IF(W5="","",IF(WEEKDAY(W5)=1,W5+1,W5)) -> 46279 | R5: =IF(Q5="","",IF(AND(N(K5)>=3,G5<>"Perdido"),"Mover para Perdido",IF(Q5<TODAY(),"Atrasado",IF(Q5=TODAY(),"Hoje","No prazo")))) -> Atrasado | S5: Pediu foto de antes e depois: só com autorização escrita | V5: não respondeu | W5: =IF(G5="","",IF(OR(G5="Novo contato",G5="Em conversa"),IF(J5="",TODAY(),J5+1),IF(G5="Avaliação marcada",IF(L5="",TODAY(),L5-1),IF(G5="Proposta enviada",IF(J5="",TODAY(),J5+2),IF(G5="Fechou pacote",IF(J5="",TODAY(),J5+7),IF(G5="Em tratamento",IF(M5="",TODAY(),IF(TODAY()<=M5+1,M5+1,EDATE(M5,6)-30)),IF(G5="Pós-venda",IF(J5="",TODAY(),J5+7),IF(G5="Perdido",IF(J5="",TODAY(),J5+60),"")))))))) -> 46279
A6: Cliente 005 | B6: (15) 99999-5967 | C6: A completar | E6: Peeling de diamante | F6: =IF(OR(E6="",E6="A completar",E6="Ainda não sabe"),"",IF(OR(E6="Limpeza de pele",E6="Peeling de diamante",E6="Microagulhamento"),"Rosto","Corpo")) -> Rosto | G6: Proposta enviada | H6: achou caro | I6: Nina | J6: 46295 | K6: 0 | P6: =IF(M6="","",EDATE(M6,6)) | Q6: =IF(W6="","",IF(WEEKDAY(W6)=1,W6+1,W6)) -> 46297 | R6: =IF(Q6="","",IF(AND(N(K6)>=3,G6<>"Perdido"),"Mover para Perdido",IF(Q6<TODAY(),"Atrasado",IF(Q6=TODAY(),"Hoje","No prazo")))) -> Atrasado | V6: achou caro | W6: =IF(G6="","",IF(OR(G6="Novo contato",G6="Em conversa"),IF(J6="",TODAY(),J6+1),IF(G6="Avaliação marcada",IF(L6="",TODAY(),L6-1),IF(G6="Proposta enviada",IF(J6="",TODAY(),J6+2),IF(G6="Fechou pacote",IF(J6="",TODAY(),J6+7),IF(G6="Em tratamento",IF(M6="",TODAY(),IF(TODAY()<=M6+1,M6+1,EDATE(M6,6)-30)),IF(G6="Pós-venda",IF(J6="",TODAY(),J6+7),IF(G6="Perdido",IF(J6="",TODAY(),J6+60),"")))))))) -> 46297
A7: Cliente 006 | B7: (15) 99999-4307 | C7: Instagram (anúncio) | E7: Criolipólise | F7: =IF(OR(E7="",E7="A completar",E7="Ainda não sabe"),"",IF(OR(E7="Limpeza de pele",E7="Peeling de diamante",E7="Microagulhamento"),"Rosto","Corpo")) -> Corpo | G7: Em conversa | I7: Nina | J7: 46267 | K7: 1 | P7: =IF(M7="","",EDATE(M7,6)) | Q7: =IF(W7="","",IF(WEEKDAY(W7)=1,W7+1,W7)) -> 46268 | R7: =IF(Q7="","",IF(AND(N(K7)>=3,G7<>"Perdido"),"Mover para Perdido",IF(Q7<TODAY(),"Atrasado",IF(Q7=TODAY(),"Hoje","No prazo")))) -> Atrasado | S7: Já fez em outra clínica | V7: não respondeu | W7: =IF(G7="","",IF(OR(G7="Novo contato",G7="Em conversa"),IF(J7="",TODAY(),J7+1),IF(G7="Avaliação marcada",IF(L7="",TODAY(),L7-1),IF(G7="Proposta enviada",IF(J7="",TODAY(),J7+2),IF(G7="Fechou pacote",IF(J7="",TODAY(),J7+7),IF(G7="Em tratamento",IF(M7="",TODAY(),IF(TODAY()<=M7+1,M7+1,EDATE(M7,6)-30)),IF(G7="Pós-venda",IF(J7="",TODAY(),J7+7),IF(G7="Perdido",IF(J7="",TODAY(),J7+60),"")))))))) -> 46268
A8: Cliente 007 | B8: (15) 99999-3319 | C8: Instagram | E8: Peeling de diamante | F8: =IF(OR(E8="",E8="A completar",E8="Ainda não sabe"),"",IF(OR(E8="Limpeza de pele",E8="Peeling de diamante",E8="Microagulhamento"),"Rosto","Corpo")) -> Rosto | G8: Proposta enviada | I8: Nina | J8: 46291 | K8: 0 | P8: =IF(M8="","",EDATE(M8,6)) | Q8: =IF(W8="","",IF(WEEKDAY(W8)=1,W8+1,W8)) -> 46293 | R8: =IF(Q8="","",IF(AND(N(K8)>=3,G8<>"Perdido"),"Mover para Perdido",IF(Q8<TODAY(),"Atrasado",IF(Q8=TODAY(),"Hoje","No prazo")))) -> Atrasado | S8: Só pode sábado | V8: fez avaliação | W8: =IF(G8="","",IF(OR(G8="Novo contato",G8="Em conversa"),IF(J8="",TODAY(),J8+1),IF(G8="Avaliação marcada",IF(L8="",TODAY(),L8-1),IF(G8="Proposta enviada",IF(J8="",TODAY(),J8+2),IF(G8="Fechou pacote",IF(J8="",TODAY(),J8+7),IF(G8="Em tratamento",IF(M8="",TODAY(),IF(TODAY()<=M8+1,M8+1,EDATE(M8,6)-30)),IF(G8="Pós-venda",IF(J8="",TODAY(),J8+7),IF(G8="Perdido",IF(J8="",TODAY(),J8+60),"")))))))) -> 46293
A9: Cliente 008 | B9: (15) 99999-4589 | C9: A completar | E9: Criolipólise | F9: =IF(OR(E9="",E9="A completar",E9="Ainda não sabe"),"",IF(OR(E9="Limpeza de pele",E9="Peeling de diamante",E9="Microagulhamento"),"Rosto","Corpo")) -> Corpo | G9: Em conversa | I9: Nina | J9: 46281 | K9: 0 | P9: =IF(M9="","",EDATE(M9,6)) | Q9: =IF(W9="","",IF(WEEKDAY(W9)=1,W9+1,W9)) -> 46282 | R9: =IF(Q9="","",IF(AND(N(K9)>=3,G9<>"Perdido"),"Mover para Perdido",IF(Q9<TODAY(),"Atrasado",IF(Q9=TODAY(),"Hoje","No prazo")))) -> Atrasado | S9: Já fez em outra clínica | V9: ligar de novo | W9: =IF(G9="","",IF(OR(G9="Novo contato",G9="Em conversa"),IF(J9="",TODAY(),J9+1),IF(G9="Avaliação marcada",IF(L9="",TODAY(),L9-1),IF(G9="Proposta enviada",IF(J9="",TODAY(),J9+2),IF(G9="Fechou pacote",IF(J9="",TODAY(),J9+7),IF(G9="Em tratamento",IF(M9="",TODAY(),IF(TODAY()<=M9+1,M9+1,EDATE(M9,6)-30)),IF(G9="Pós-venda",IF(J9="",TODAY(),J9+7),IF(G9="Perdido",IF(J9="",TODAY(),J9+60),"")))))))) -> 46282
A10: Cliente 009 | B10: (15) 99999-3861 | C10: Indicação | E10: Peeling de diamante | F10: =IF(OR(E10="",E10="A completar",E10="Ainda não sabe"),"",IF(OR(E10="Limpeza de pele",E10="Peeling de diamante",E10="Microagulhamento"),"Rosto","Corpo")) -> Rosto | G10: Avaliação marcada | I10: Nina | J10: 46293 | K10: 0 | P10: =IF(M10="","",EDATE(M10,6)) | Q10: =IF(W10="","",IF(WEEKDAY(W10)=1,W10+1,W10)) -> 46309 | R10: =IF(Q10="","",IF(AND(N(K10)>=3,G10<>"Perdido"),"Mover para Perdido",IF(Q10<TODAY(),"Atrasado",IF(Q10=TODAY(),"Hoje","No prazo")))) -> Hoje | V10: avaliação? | W10: =IF(G10="","",IF(OR(G10="Novo contato",G10="Em conversa"),IF(J10="",TODAY(),J10+1),IF(G10="Avaliação marcada",IF(L10="",TODAY(),L10-1),IF(G10="Proposta enviada",IF(J10="",TODAY(),J10+2),IF(G10="Fechou pacote",IF(J10="",TODAY(),J10+7),IF(G10="Em tratamento",IF(M10="",TODAY(),IF(TODAY()<=M10+1,M10+1,EDATE(M10,6)-30)),IF(G10="Pós-venda",IF(J10="",TODAY(),J10+7),IF(G10="Perdido",IF(J10="",TODAY(),J10+60),"")))))))) -> 46309
A11: Cliente 010 | B11: (15) 99999-7596 | C11: A completar | E11: Drenagem linfática | F11: =IF(OR(E11="",E11="A completar",E11="Ainda não sabe"),"",IF(OR(E11="Limpeza de pele",E11="Peeling de diamante",E11="Microagulhamento"),"Rosto","Corpo")) -> Corpo | G11: Avaliação marcada | I11: Nina | J11: 46278 | K11: 0 | P11: =IF(M11="","",EDATE(M11,6)) | Q11: =IF(W11="","",IF(WEEKDAY(W11)=1,W11+1,W11)) -> 46309 | R11: =IF(Q11="","",IF(AND(N(K11)>=3,G11<>"Perdido"),"Mover para Perdido",IF(Q11<TODAY(),"Atrasado",IF(Q11=TODAY(),"Hoje","No prazo")))) -> Hoje | S11: Perguntou do resultado: nunca prometer cm ou kg | V11: remarcar | W11: =IF(G11="","",IF(OR(G11="Novo contato",G11="Em conversa"),IF(J11="",TODAY(),J11+1),IF(G11="Avaliação marcada",IF(L11="",TODAY(),L11-1),IF(G11="Proposta enviada",IF(J11="",TODAY(),J11+2),IF(G11="Fechou pacote",IF(J11="",TODAY(),J11+7),IF(G11="Em tratamento",IF(M11="",TODAY(),IF(TODAY()<=M11+1,M11+1,EDATE(M11,6)-30)),IF(G11="Pós-venda",IF(J11="",TODAY(),J11+7),IF(G11="Perdido",IF(J11="",TODAY(),J11+60),"")))))))) -> 46309
A12: Cliente 011 | B12: (15) 99999-8159 | C12: Instagram (anúncio) | E12: Massagem modeladora | F12: =IF(OR(E12="",E12="A completar",E12="Ainda não sabe"),"",IF(OR(E12="Limpeza de pele",E12="Peeling de diamante",E12="Microagulhamento"),"Rosto","Corpo")) -> Corpo | G12: Avaliação marcada | I12: Nina | J12: 46228 | K12: 0 | P12: =IF(M12="","",EDATE(M12,6)) | Q12: =IF(W12="","",IF(WEEKDAY(W12)=1,W12+1,W12)) -> 46309 | R12: =IF(Q12="","",IF(AND(N(K12)>=3,G12<>"Perdido"),"Mover para Perdido",IF(Q12<TODAY(),"Atrasado",IF(Q12=TODAY(),"Hoje","No prazo")))) -> Hoje | S12: Perguntou do resultado: nunca prometer cm ou kg | V12: avaliação? | W12: =IF(G12="","",IF(OR(G12="Novo contato",G12="Em conversa"),IF(J12="",TODAY(),J12+1),IF(G12="Avaliação marcada",IF(L12="",TODAY(),L12-1),IF(G12="Proposta enviada",IF(J12="",TODAY(),J12+2),IF(G12="Fechou pacote",IF(J12="",TODAY(),J12+7),IF(G12="Em tratamento",IF(M12="",TODAY(),IF(TODAY()<=M12+1,M12+1,EDATE(M12,6)-30)),IF(G12="Pós-venda",IF(J12="",TODAY(),J12+7),IF(G12="Perdido",IF(J12="",TODAY(),J12+60),"")))))))) -> 46309
A13: Cliente 012 | B13: (15) 99999-5744 | C13: Indicação | E13: Peeling de diamante | F13: =IF(OR(E13="",E13="A completar",E13="Ainda não sabe"),"",IF(OR(E13="Limpeza de pele",E13="Peeling de diamante",E13="Microagulhamento"),"Rosto","Corpo")) -> Rosto | G13: Novo contato | I13: Nina | J13: 46255 | K13: 0 | P13: =IF(M13="","",EDATE(M13,6)) | Q13: =IF(W13="","",IF(WEEKDAY(W13)=1,W13+1,W13)) -> 46256 | R13: =IF(Q13="","",IF(AND(N(K13)>=3,G13<>"Perdido"),"Mover para Perdido",IF(Q13<TODAY(),"Atrasado",IF(Q13=TODAY(),"Hoje","No prazo")))) -> Atrasado | V13: (em branco) | W13: =IF(G13="","",IF(OR(G13="Novo contato",G13="Em conversa"),IF(J13="",TODAY(),J13+1),IF(G13="Avaliação marcada",IF(L13="",TODAY(),L13-1),IF(G13="Proposta enviada",IF(J13="",TODAY(),J13+2),IF(G13="Fechou pacote",IF(J13="",TODAY(),J13+7),IF(G13="Em tratamento",IF(M13="",TODAY(),IF(TODAY()<=M13+1,M13+1,EDATE(M13,6)-30)),IF(G13="Pós-venda",IF(J13="",TODAY(),J13+7),IF(G13="Perdido",IF(J13="",TODAY(),J13+60),"")))))))) -> 46256
A14: Cliente 013 | B14: (15) 99999-8132 | C14: Indicação | E14: Drenagem linfática | F14: =IF(OR(E14="",E14="A completar",E14="Ainda não sabe"),"",IF(OR(E14="Limpeza de pele",E14="Peeling de diamante",E14="Microagulhamento"),"Rosto","Corpo")) -> Corpo | G14: Em conversa | I14: Nina | J14: 46300 | K14: 0 | P14: =IF(M14="","",EDATE(M14,6)) | Q14: =IF(W14="","",IF(WEEKDAY(W14)=1,W14+1,W14)) -> 46301 | R14: =IF(Q14="","",IF(AND(N(K14)>=3,G14<>"Perdido"),"Mover para Perdido",IF(Q14<TODAY(),"Atrasado",IF(Q14=TODAY(),"Hoje","No prazo")))) -> Atrasado | S14: Prefere áudio | V14: ligar de novo | W14: =IF(G14="","",IF(OR(G14="Novo contato",G14="Em conversa"),IF(J14="",TODAY(),J14+1),IF(G14="Avaliação marcada",IF(L14="",TODAY(),L14-1),IF(G14="Proposta enviada",IF(J14="",TODAY(),J14+2),IF(G14="Fechou pacote",IF(J14="",TODAY(),J14+7),IF(G14="Em tratamento",IF(M14="",TODAY(),IF(TODAY()<=M14+1,M14+1,EDATE(M14,6)-30)),IF(G14="Pós-venda",IF(J14="",TODAY(),J14+7),IF(G14="Perdido",IF(J14="",TODAY(),J14+60),"")))))))) -> 46301
A15: Cliente 014 | B15: (15) 99999-9337 | C15: Indicação | D15: Amiga (confirmar nome) | E15: Criolipólise | F15: =IF(OR(E15="",E15="A completar",E15="Ainda não sabe"),"",IF(OR(E15="Limpeza de pele",E15="Peeling de diamante",E15="Microagulhamento"),"Rosto","Corpo")) -> Corpo | G15: Proposta enviada | I15: Nina | J15: 46227 | K15: 0 | P15: =IF(M15="","",EDATE(M15,6)) | Q15: =IF(W15="","",IF(WEEKDAY(W15)=1,W15+1,W15)) -> 46230 | R15: =IF(Q15="","",IF(AND(N(K15)>=3,G15<>"Perdido"),"Mover para Perdido",IF(Q15<TODAY(),"Atrasado",IF(Q15=TODAY(),"Hoje","No prazo")))) -> Atrasado | U15: Na planilha antiga a origem era Google, mas a cliente veio pela amiga. | V15: fez avaliação | W15: =IF(G15="","",IF(OR(G15="Novo contato",G15="Em conversa"),IF(J15="",TODAY(),J15+1),IF(G15="Avaliação marcada",IF(L15="",TODAY(),L15-1),IF(G15="Proposta enviada",IF(J15="",TODAY(),J15+2),IF(G15="Fechou pacote",IF(J15="",TODAY(),J15+7),IF(G15="Em tratamento",IF(M15="",TODAY(),IF(TODAY()<=M15+1,M15+1,EDATE(M15,6)-30)),IF(G15="Pós-venda",IF(J15="",TODAY(),J15+7),IF(G15="Perdido",IF(J15="",TODAY(),J15+60),"")))))))) -> 46229
A16: Cliente 015 | B16: (15) 99999-9097 | C16: Instagram | E16: Depilação a laser | F16: =IF(OR(E16="",E16="A completar",E16="Ainda não sabe"),"",IF(OR(E16="Limpeza de pele",E16="Peeling de diamante",E16="Microagulhamento"),"Rosto","Corpo")) -> Corpo | G16: Avaliação marcada | I16: Nina | J16: 46244 | K16: 0 | P16: =IF(M16="","",EDATE(M16,6)) | Q16: =IF(W16="","",IF(WEEKDAY(W16)=1,W16+1,W16)) -> 46309 | R16: =IF(Q16="","",IF(AND(N(K16)>=3,G16<>"Perdido"),"Mover para Perdido",IF(Q16<TODAY(),"Atrasado",IF(Q16=TODAY(),"Hoje","No prazo")))) -> Hoje | V16: avaliação? | W16: =IF(G16="","",IF(OR(G16="Novo contato",G16="Em conversa"),IF(J16="",TODAY(),J16+1),IF(G16="Avaliação marcada",IF(L16="",TODAY(),L16-1),IF(G16="Proposta enviada",IF(J16="",TODAY(),J16+2),IF(G16="Fechou pacote",IF(J16="",TODAY(),J16+7),IF(G16="Em tratamento",IF(M16="",TODAY(),IF(TODAY()<=M16+1,M16+1,EDATE(M16,6)-30)),IF(G16="Pós-venda",IF(J16="",TODAY(),J16+7),IF(G16="Perdido",IF(J16="",TODAY(),J16+60),"")))))))) -> 46309
A17: Cliente 016 | B17: (15) 99999-9112 | C17: Instagram | E17: A completar | F17: =IF(OR(E17="",E17="A completar",E17="Ainda não sabe"),"",IF(OR(E17="Limpeza de pele",E17="Peeling de diamante",E17="Microagulhamento"),"Rosto","Corpo")) | G17: Fechou pacote | I17: Nina | J17: 46277 | K17: 0 | P17: =IF(M17="","",EDATE(M17,6)) | Q17: =IF(W17="","",IF(WEEKDAY(W17)=1,W17+1,W17)) -> 46284 | R17: =IF(Q17="","",IF(AND(N(K17)>=3,G17<>"Perdido"),"Mover para Perdido",IF(Q17<TODAY(),"Atrasado",IF(Q17=TODAY(),"Hoje","No prazo")))) -> Atrasado | V17: fechou pacote | W17: =IF(G17="","",IF(OR(G17="Novo contato",G17="Em conversa"),IF(J17="",TODAY(),J17+1),IF(G17="Avaliação marcada",IF(L17="",TODAY(),L17-1),IF(G17="Proposta enviada",IF(J17="",TODAY(),J17+2),IF(G17="Fechou pacote",IF(J17="",TODAY(),J17+7),IF(G17="Em tratamento",IF(M17="",TODAY(),IF(TODAY()<=M17+1,M17+1,EDATE(M17,6)-30)),IF(G17="Pós-venda",IF(J17="",TODAY(),J17+7),IF(G17="Perdido",IF(J17="",TODAY(),J17+60),"")))))))) -> 46284
A18: Cliente 017 | B18: (15) 99999-5088 | C18: Instagram | E18: Microagulhamento | F18: =IF(OR(E18="",E18="A completar",E18="Ainda não sabe"),"",IF(OR(E18="Limpeza de pele",E18="Peeling de diamante",E18="Microagulhamento"),"Rosto","Corpo")) -> Rosto | G18: Proposta enviada | H18: quer parcelar | I18: Nina | K18: 0 | P18: =IF(M18="","",EDATE(M18,6)) | Q18: =IF(W18="","",IF(WEEKDAY(W18)=1,W18+1,W18)) -> 46309 | R18: =IF(Q18="","",IF(AND(N(K18)>=3,G18<>"Perdido"),"Mover para Perdido",IF(Q18<TODAY(),"Atrasado",IF(Q18=TODAY(),"Hoje","No prazo")))) -> Hoje | S18: Quer parcelar | V18: fez avaliação | W18: =IF(G18="","",IF(OR(G18="Novo contato",G18="Em conversa"),IF(J18="",TODAY(),J18+1),IF(G18="Avaliação marcada",IF(L18="",TODAY(),L18-1),IF(G18="Proposta enviada",IF(J18="",TODAY(),J18+2),IF(G18="Fechou pacote",IF(J18="",TODAY(),J18+7),IF(G18="Em tratamento",IF(M18="",TODAY(),IF(TODAY()<=M18+1,M18+1,EDATE(M18,6)-30)),IF(G18="Pós-venda",IF(J18="",TODAY(),J18+7),IF(G18="Perdido",IF(J18="",TODAY(),J18+60),"")))))))) -> 46309
A19: Cliente 018 | B19: (15) 99999-1268 | C19: Instagram (anúncio) | E19: Peeling de diamante | F19: =IF(OR(E19="",E19="A completar",E19="Ainda não sabe"),"",IF(OR(E19="Limpeza de pele",E19="Peeling de diamante",E19="Microagulhamento"),"Rosto","Corpo")) -> Rosto | G19: Em conversa | I19: Nina | J19: 46295 | K19: 0 | P19: =IF(M19="","",EDATE(M19,6)) | Q19: =IF(W19="","",IF(WEEKDAY(W19)=1,W19+1,W19)) -> 46296 | R19: =IF(Q19="","",IF(AND(N(K19)>=3,G19<>"Perdido"),"Mover para Perdido",IF(Q19<TODAY(),"Atrasado",IF(Q19=TODAY(),"Hoje","No prazo")))) -> Atrasado | V19: pediu preço | W19: =IF(G19="","",IF(OR(G19="Novo contato",G19="Em conversa"),IF(J19="",TODAY(),J19+1),IF(G19="Avaliação marcada",IF(L19="",TODAY(),L19-1),IF(G19="Proposta enviada",IF(J19="",TODAY(),J19+2),IF(G19="Fechou pacote",IF(J19="",TODAY(),J19+7),IF(G19="Em tratamento",IF(M19="",TODAY(),IF(TODAY()<=M19+1,M19+1,EDATE(M19,6)-30)),IF(G19="Pós-venda",IF(J19="",TODAY(),J19+7),IF(G19="Perdido",IF(J19="",TODAY(),J19+60),"")))))))) -> 46296
A20: Cliente 019 | B20: (15) 99999-8135 | C20: Indicação | D20: Amiga (confirmar nome) | E20: Depilação a laser | F20: =IF(OR(E20="",E20="A completar",E20="Ainda não sabe"),"",IF(OR(E20="Limpeza de pele",E20="Peeling de diamante",E20="Microagulhamento"),"Rosto","Corpo")) -> Corpo | G20: Proposta enviada | H20: achou caro | I20: Nina | J20: 46263 | K20: 0 | P20: =IF(M20="","",EDATE(M20,6)) | Q20: =IF(W20="","",IF(WEEKDAY(W20)=1,W20+1,W20)) -> 46265 | R20: =IF(Q20="","",IF(AND(N(K20)>=3,G20<>"Perdido"),"Mover para Perdido",IF(Q20<TODAY(),"Atrasado",IF(Q20=TODAY(),"Hoje","No prazo")))) -> Atrasado | U20: Na planilha antiga a origem era Instagram (anúncio), mas a cliente veio pela amiga. | V20: achou caro | W20: =IF(G20="","",IF(OR(G20="Novo contato",G20="Em conversa"),IF(J20="",TODAY(),J20+1),IF(G20="Avaliação marcada",IF(L20="",TODAY(),L20-1),IF(G20="Proposta enviada",IF(J20="",TODAY(),J20+2),IF(G20="Fechou pacote",IF(J20="",TODAY(),J20+7),IF(G20="Em tratamento",IF(M20="",TODAY(),IF(TODAY()<=M20+1,M20+1,EDATE(M20,6)-30)),IF(G20="Pós-venda",IF(J20="",TODAY(),J20+7),IF(G20="Perdido",IF(J20="",TODAY(),J20+60),"")))))))) -> 46265
A21: Cliente 020 | B21: (15) 99999-6163 | C21: Instagram | E21: Criolipólise | F21: =IF(OR(E21="",E21="A completar",E21="Ainda não sabe"),"",IF(OR(E21="Limpeza de pele",E21="Peeling de diamante",E21="Microagulhamento"),"Rosto","Corpo")) -> Corpo | G21: Proposta enviada | I21: Nina | J21: 46260 | K21: 0 | P21: =IF(M21="","",EDATE(M21,6)) | Q21: =IF(W21="","",IF(WEEKDAY(W21)=1,W21+1,W21)) -> 46262 | R21: =IF(Q21="","",IF(AND(N(K21)>=3,G21<>"Perdido"),"Mover para Perdido",IF(Q21<TODAY(),"Atrasado",IF(Q21=TODAY(),"Hoje","No prazo")))) -> Atrasado | S21: Perguntou do resultado: nunca prometer cm ou kg | V21: fez avaliação | W21: =IF(G21="","",IF(OR(G21="Novo contato",G21="Em conversa"),IF(J21="",TODAY(),J21+1),IF(G21="Avaliação marcada",IF(L21="",TODAY(),L21-1),IF(G21="Proposta enviada",IF(J21="",TODAY(),J21+2),IF(G21="Fechou pacote",IF(J21="",TODAY(),J21+7),IF(G21="Em tratamento",IF(M21="",TODAY(),IF(TODAY()<=M21+1,M21+1,EDATE(M21,6)-30)),IF(G21="Pós-venda",IF(J21="",TODAY(),J21+7),IF(G21="Perdido",IF(J21="",TODAY(),J21+60),"")))))))) -> 46262
A22: Cliente 021 | B22: (15) 99999-9633 | C22: Indicação | E22: Peeling de diamante | F22: =IF(OR(E22="",E22="A completar",E22="Ainda não sabe"),"",IF(OR(E22="Limpeza de pele",E22="Peeling de diamante",E22="Microagulhamento"),"Rosto","Corpo")) -> Rosto | G22: Avaliação marcada | I22: Nina | J22: 46250 | K22: 0 | P22: =IF(M22="","",EDATE(M22,6)) | Q22: =IF(W22="","",IF(WEEKDAY(W22)=1,W22+1,W22)) -> 46309 | R22: =IF(Q22="","",IF(AND(N(K22)>=3,G22<>"Perdido"),"Mover para Perdido",IF(Q22<TODAY(),"Atrasado",IF(Q22=TODAY(),"Hoje","No prazo")))) -> Hoje | S22: Prefere áudio | V22: marcou avaliação | W22: =IF(G22="","",IF(OR(G22="Novo contato",G22="Em conversa"),IF(J22="",TODAY(),J22+1),IF(G22="Avaliação marcada",IF(L22="",TODAY(),L22-1),IF(G22="Proposta enviada",IF(J22="",TODAY(),J22+2),IF(G22="Fechou pacote",IF(J22="",TODAY(),J22+7),IF(G22="Em tratamento",IF(M22="",TODAY(),IF(TODAY()<=M22+1,M22+1,EDATE(M22,6)-30)),IF(G22="Pós-venda",IF(J22="",TODAY(),J22+7),IF(G22="Perdido",IF(J22="",TODAY(),J22+60),"")))))))) -> 46309
A23: Cliente 022 | B23: (15) 99999-5747 | C23: A completar | E23: Drenagem linfática | F23: =IF(OR(E23="",E23="A completar",E23="Ainda não sabe"),"",IF(OR(E23="Limpeza de pele",E23="Peeling de diamante",E23="Microagulhamento"),"Rosto","Corpo")) -> Corpo | G23: Fechou pacote | I23: Nina | J23: 46259 | K23: 0 | P23: =IF(M23="","",EDATE(M23,6)) | Q23: =IF(W23="","",IF(WEEKDAY(W23)=1,W23+1,W23)) -> 46266 | R23: =IF(Q23="","",IF(AND(N(K23)>=3,G23<>"Perdido"),"Mover para Perdido",IF(Q23<TODAY(),"Atrasado",IF(Q23=TODAY(),"Hoje","No prazo")))) -> Atrasado | S23: Perguntou do resultado: nunca prometer cm ou kg | V23: fechou pacote | W23: =IF(G23="","",IF(OR(G23="Novo contato",G23="Em conversa"),IF(J23="",TODAY(),J23+1),IF(G23="Avaliação marcada",IF(L23="",TODAY(),L23-1),IF(G23="Proposta enviada",IF(J23="",TODAY(),J23+2),IF(G23="Fechou pacote",IF(J23="",TODAY(),J23+7),IF(G23="Em tratamento",IF(M23="",TODAY(),IF(TODAY()<=M23+1,M23+1,EDATE(M23,6)-30)),IF(G23="Pós-venda",IF(J23="",TODAY(),J23+7),IF(G23="Perdido",IF(J23="",TODAY(),J23+60),"")))))))) -> 46266
A24: Cliente 023 | B24: (15) 99999-0747 | C24: Instagram | E24: Massagem modeladora | F24: =IF(OR(E24="",E24="A completar",E24="Ainda não sabe"),"",IF(OR(E24="Limpeza de pele",E24="Peeling de diamante",E24="Microagulhamento"),"Rosto","Corpo")) -> Corpo | G24: Avaliação marcada | I24: Nina | K24: 0 | P24: =IF(M24="","",EDATE(M24,6)) | Q24: =IF(W24="","",IF(WEEKDAY(W24)=1,W24+1,W24)) -> 46309 | R24: =IF(Q24="","",IF(AND(N(K24)>=3,G24<>"Perdido"),"Mover para Perdido",IF(Q24<TODAY(),"Atrasado",IF(Q24=TODAY(),"Hoje","No prazo")))) -> Hoje | S24: Já fez em outra clínica | V24: marcou avaliação | W24: =IF(G24="","",IF(OR(G24="Novo contato",G24="Em conversa"),IF(J24="",TODAY(),J24+1),IF(G24="Avaliação marcada",IF(L24="",TODAY(),L24-1),IF(G24="Proposta enviada",IF(J24="",TODAY(),J24+2),IF(G24="Fechou pacote",IF(J24="",TODAY(),J24+7),IF(G24="Em tratamento",IF(M24="",TODAY(),IF(TODAY()<=M24+1,M24+1,EDATE(M24,6)-30)),IF(G24="Pós-venda",IF(J24="",TODAY(),J24+7),IF(G24="Perdido",IF(J24="",TODAY(),J24+60),"")))))))) -> 46309
A25: Cliente 024 | B25: (15) 99999-6384 | C25: Google | E25: Drenagem linfática | F25: =IF(OR(E25="",E25="A completar",E25="Ainda não sabe"),"",IF(OR(E25="Limpeza de pele",E25="Peeling de diamante",E25="Microagulhamento"),"Rosto","Corpo")) -> Corpo | G25: Proposta enviada | I25: Nina | J25: 46284 | K25: 0 | P25: =IF(M25="","",EDATE(M25,6)) | Q25: =IF(W25="","",IF(WEEKDAY(W25)=1,W25+1,W25)) -> 46286 | R25: =IF(Q25="","",IF(AND(N(K25)>=3,G25<>"Perdido"),"Mover para Perdido",IF(Q25<TODAY(),"Atrasado",IF(Q25=TODAY(),"Hoje","No prazo")))) -> Atrasado | S25: Pediu foto de antes e depois: só com autorização escrita | V25: fez avaliação | W25: =IF(G25="","",IF(OR(G25="Novo contato",G25="Em conversa"),IF(J25="",TODAY(),J25+1),IF(G25="Avaliação marcada",IF(L25="",TODAY(),L25-1),IF(G25="Proposta enviada",IF(J25="",TODAY(),J25+2),IF(G25="Fechou pacote",IF(J25="",TODAY(),J25+7),IF(G25="Em tratamento",IF(M25="",TODAY(),IF(TODAY()<=M25+1,M25+1,EDATE(M25,6)-30)),IF(G25="Pós-venda",IF(J25="",TODAY(),J25+7),IF(G25="Perdido",IF(J25="",TODAY(),J25+60),"")))))))) -> 46286
A26: Cliente 025 | B26: (15) 99999-2430 | C26: Instagram | E26: Limpeza de pele | F26: =IF(OR(E26="",E26="A completar",E26="Ainda não sabe"),"",IF(OR(E26="Limpeza de pele",E26="Peeling de diamante",E26="Microagulhamento"),"Rosto","Corpo")) -> Rosto | G26: Fechou pacote | I26: Nina | J26: 46278 | K26: 0 | P26: =IF(M26="","",EDATE(M26,6)) | Q26: =IF(W26="","",IF(WEEKDAY(W26)=1,W26+1,W26)) -> 46286 | R26: =IF(Q26="","",IF(AND(N(K26)>=3,G26<>"Perdido"),"Mover para Perdido",IF(Q26<TODAY(),"Atrasado",IF(Q26=TODAY(),"Hoje","No prazo")))) -> Atrasado | V26: fechou pacote | W26: =IF(G26="","",IF(OR(G26="Novo contato",G26="Em conversa"),IF(J26="",TODAY(),J26+1),IF(G26="Avaliação marcada",IF(L26="",TODAY(),L26-1),IF(G26="Proposta enviada",IF(J26="",TODAY(),J26+2),IF(G26="Fechou pacote",IF(J26="",TODAY(),J26+7),IF(G26="Em tratamento",IF(M26="",TODAY(),IF(TODAY()<=M26+1,M26+1,EDATE(M26,6)-30)),IF(G26="Pós-venda",IF(J26="",TODAY(),J26+7),IF(G26="Perdido",IF(J26="",TODAY(),J26+60),"")))))))) -> 46285
A27: Cliente 026 | B27: (15) 99999-9883 | C27: A completar | E27: Massagem modeladora | F27: =IF(OR(E27="",E27="A completar",E27="Ainda não sabe"),"",IF(OR(E27="Limpeza de pele",E27="Peeling de diamante",E27="Microagulhamento"),"Rosto","Corpo")) -> Corpo | G27: Em conversa | I27: Nina | J27: 46250 | K27: 0 | P27: =IF(M27="","",EDATE(M27,6)) | Q27: =IF(W27="","",IF(WEEKDAY(W27)=1,W27+1,W27)) -> 46251 | R27: =IF(Q27="","",IF(AND(N(K27)>=3,G27<>"Perdido"),"Mover para Perdido",IF(Q27<TODAY(),"Atrasado",IF(Q27=TODAY(),"Hoje","No prazo")))) -> Atrasado | S27: Só pode sábado | V27: pediu preço | W27: =IF(G27="","",IF(OR(G27="Novo contato",G27="Em conversa"),IF(J27="",TODAY(),J27+1),IF(G27="Avaliação marcada",IF(L27="",TODAY(),L27-1),IF(G27="Proposta enviada",IF(J27="",TODAY(),J27+2),IF(G27="Fechou pacote",IF(J27="",TODAY(),J27+7),IF(G27="Em tratamento",IF(M27="",TODAY(),IF(TODAY()<=M27+1,M27+1,EDATE(M27,6)-30)),IF(G27="Pós-venda",IF(J27="",TODAY(),J27+7),IF(G27="Perdido",IF(J27="",TODAY(),J27+60),"")))))))) -> 46251
A28: Cliente 027 | B28: (15) 99999-8042 | C28: Instagram (anúncio) | E28: Microagulhamento | F28: =IF(OR(E28="",E28="A completar",E28="Ainda não sabe"),"",IF(OR(E28="Limpeza de pele",E28="Peeling de diamante",E28="Microagulhamento"),"Rosto","Corpo")) -> Rosto | G28: Em conversa | I28: Nina | K28: 0 | P28: =IF(M28="","",EDATE(M28,6)) | Q28: =IF(W28="","",IF(WEEKDAY(W28)=1,W28+1,W28)) -> 46309 | R28: =IF(Q28="","",IF(AND(N(K28)>=3,G28<>"Perdido"),"Mover para Perdido",IF(Q28<TODAY(),"Atrasado",IF(Q28=TODAY(),"Hoje","No prazo")))) -> Hoje | S28: Só pode sábado | V28: pediu preço | W28: =IF(G28="","",IF(OR(G28="Novo contato",G28="Em conversa"),IF(J28="",TODAY(),J28+1),IF(G28="Avaliação marcada",IF(L28="",TODAY(),L28-1),IF(G28="Proposta enviada",IF(J28="",TODAY(),J28+2),IF(G28="Fechou pacote",IF(J28="",TODAY(),J28+7),IF(G28="Em tratamento",IF(M28="",TODAY(),IF(TODAY()<=M28+1,M28+1,EDATE(M28,6)-30)),IF(G28="Pós-venda",IF(J28="",TODAY(),J28+7),IF(G28="Perdido",IF(J28="",TODAY(),J28+60),"")))))))) -> 46309
A29: Cliente 028 | B29: (15) 99999-0805 | C29: Google | E29: Criolipólise | F29: =IF(OR(E29="",E29="A completar",E29="Ainda não sabe"),"",IF(OR(E29="Limpeza de pele",E29="Peeling de diamante",E29="Microagulhamento"),"Rosto","Corpo")) -> Corpo | G29: Novo contato | I29: Nina | J29: 46291 | K29: 0 | P29: =IF(M29="","",EDATE(M29,6)) | Q29: =IF(W29="","",IF(WEEKDAY(W29)=1,W29+1,W29)) -> 46293 | R29: =IF(Q29="","",IF(AND(N(K29)>=3,G29<>"Perdido"),"Mover para Perdido",IF(Q29<TODAY(),"Atrasado",IF(Q29=TODAY(),"Hoje","No prazo")))) -> Atrasado | V29: (em branco) | W29: =IF(G29="","",IF(OR(G29="Novo contato",G29="Em conversa"),IF(J29="",TODAY(),J29+1),IF(G29="Avaliação marcada",IF(L29="",TODAY(),L29-1),IF(G29="Proposta enviada",IF(J29="",TODAY(),J29+2),IF(G29="Fechou pacote",IF(J29="",TODAY(),J29+7),IF(G29="Em tratamento",IF(M29="",TODAY(),IF(TODAY()<=M29+1,M29+1,EDATE(M29,6)-30)),IF(G29="Pós-venda",IF(J29="",TODAY(),J29+7),IF(G29="Perdido",IF(J29="",TODAY(),J29+60),"")))))))) -> 46292
A30: Cliente 029 | B30: (15) 99999-2453 | C30: Instagram | E30: A completar | F30: =IF(OR(E30="",E30="A completar",E30="Ainda não sabe"),"",IF(OR(E30="Limpeza de pele",E30="Peeling de diamante",E30="Microagulhamento"),"Rosto","Corpo")) | G30: Fechou pacote | I30: Nina | J30: 46223 | K30: 0 | P30: =IF(M30="","",EDATE(M30,6)) | Q30: =IF(W30="","",IF(WEEKDAY(W30)=1,W30+1,W30)) -> 46230 | R30: =IF(Q30="","",IF(AND(N(K30)>=3,G30<>"Perdido"),"Mover para Perdido",IF(Q30<TODAY(),"Atrasado",IF(Q30=TODAY(),"Hoje","No prazo")))) -> Atrasado | V30: fechou pacote | W30: =IF(G30="","",IF(OR(G30="Novo contato",G30="Em conversa"),IF(J30="",TODAY(),J30+1),IF(G30="Avaliação marcada",IF(L30="",TODAY(),L30-1),IF(G30="Proposta enviada",IF(J30="",TODAY(),J30+2),IF(G30="Fechou pacote",IF(J30="",TODAY(),J30+7),IF(G30="Em tratamento",IF(M30="",TODAY(),IF(TODAY()<=M30+1,M30+1,EDATE(M30,6)-30)),IF(G30="Pós-venda",IF(J30="",TODAY(),J30+7),IF(G30="Perdido",IF(J30="",TODAY(),J30+60),"")))))))) -> 46230
A31: Cliente 030 | B31: (15) 99999-3502 | C31: Indicação | D31: Amiga (confirmar nome) | E31: Depilação a laser | F31: =IF(OR(E31="",E31="A completar",E31="Ainda não sabe"),"",IF(OR(E31="Limpeza de pele",E31="Peeling de diamante",E31="Microagulhamento"),"Rosto","Corpo")) -> Corpo | G31: Proposta enviada | H31: achou caro | I31: Nina | J31: 46267 | K31: 0 | P31: =IF(M31="","",EDATE(M31,6)) | Q31: =IF(W31="","",IF(WEEKDAY(W31)=1,W31+1,W31)) -> 46269 | R31: =IF(Q31="","",IF(AND(N(K31)>=3,G31<>"Perdido"),"Mover para Perdido",IF(Q31<TODAY(),"Atrasado",IF(Q31=TODAY(),"Hoje","No prazo")))) -> Atrasado | U31: Na planilha antiga a origem era Instagram, mas a cliente veio pela amiga. | V31: achou caro | W31: =IF(G31="","",IF(OR(G31="Novo contato",G31="Em conversa"),IF(J31="",TODAY(),J31+1),IF(G31="Avaliação marcada",IF(L31="",TODAY(),L31-1),IF(G31="Proposta enviada",IF(J31="",TODAY(),J31+2),IF(G31="Fechou pacote",IF(J31="",TODAY(),J31+7),IF(G31="Em tratamento",IF(M31="",TODAY(),IF(TODAY()<=M31+1,M31+1,EDATE(M31,6)-30)),IF(G31="Pós-venda",IF(J31="",TODAY(),J31+7),IF(G31="Perdido",IF(J31="",TODAY(),J31+60),"")))))))) -> 46269
A32: Cliente 031 | B32: (15) 99999-7217 | C32: Indicação | E32: Microagulhamento | F32: =IF(OR(E32="",E32="A completar",E32="Ainda não sabe"),"",IF(OR(E32="Limpeza de pele",E32="Peeling de diamante",E32="Microagulhamento"),"Rosto","Corpo")) -> Rosto | G32: Em conversa | I32: Nina | J32: 46289 | K32: 0 | P32: =IF(M32="","",EDATE(M32,6)) | Q32: =IF(W32="","",IF(WEEKDAY(W32)=1,W32+1,W32)) -> 46290 | R32: =IF(Q32="","",IF(AND(N(K32)>=3,G32<>"Perdido"),"Mover para Perdido",IF(Q32<TODAY(),"Atrasado",IF(Q32=TODAY(),"Hoje","No prazo")))) -> Atrasado | V32: ligar de novo | W32: =IF(G32="","",IF(OR(G32="Novo contato",G32="Em conversa"),IF(J32="",TODAY(),J32+1),IF(G32="Avaliação marcada",IF(L32="",TODAY(),L32-1),IF(G32="Proposta enviada",IF(J32="",TODAY(),J32+2),IF(G32="Fechou pacote",IF(J32="",TODAY(),J32+7),IF(G32="Em tratamento",IF(M32="",TODAY(),IF(TODAY()<=M32+1,M32+1,EDATE(M32,6)-30)),IF(G32="Pós-venda",IF(J32="",TODAY(),J32+7),IF(G32="Perdido",IF(J32="",TODAY(),J32+60),"")))))))) -> 46290
A33: Cliente 032 | B33: (15) 99999-1890 | C33: Instagram | E33: Peeling de diamante | F33: =IF(OR(E33="",E33="A completar",E33="Ainda não sabe"),"",IF(OR(E33="Limpeza de pele",E33="Peeling de diamante",E33="Microagulhamento"),"Rosto","Corpo")) -> Rosto | G33: Novo contato | I33: Nina | J33: 46293 | K33: 0 | P33: =IF(M33="","",EDATE(M33,6)) | Q33: =IF(W33="","",IF(WEEKDAY(W33)=1,W33+1,W33)) -> 46294 | R33: =IF(Q33="","",IF(AND(N(K33)>=3,G33<>"Perdido"),"Mover para Perdido",IF(Q33<TODAY(),"Atrasado",IF(Q33=TODAY(),"Hoje","No prazo")))) -> Atrasado | S33: Perguntou do resultado: nunca prometer cm ou kg | V33: (em branco) | W33: =IF(G33="","",IF(OR(G33="Novo contato",G33="Em conversa"),IF(J33="",TODAY(),J33+1),IF(G33="Avaliação marcada",IF(L33="",TODAY(),L33-1),IF(G33="Proposta enviada",IF(J33="",TODAY(),J33+2),IF(G33="Fechou pacote",IF(J33="",TODAY(),J33+7),IF(G33="Em tratamento",IF(M33="",TODAY(),IF(TODAY()<=M33+1,M33+1,EDATE(M33,6)-30)),IF(G33="Pós-venda",IF(J33="",TODAY(),J33+7),IF(G33="Perdido",IF(J33="",TODAY(),J33+60),"")))))))) -> 46294
A34: Cliente 033 | B34: (15) 99999-8937 | C34: Indicação | E34: Massagem modeladora | F34: =IF(OR(E34="",E34="A completar",E34="Ainda não sabe"),"",IF(OR(E34="Limpeza de pele",E34="Peeling de diamante",E34="Microagulhamento"),"Rosto","Corpo")) -> Corpo | G34: Proposta enviada | H34: vai pensar | I34: Nina | J34: 46261 | K34: 0 | P34: =IF(M34="","",EDATE(M34,6)) | Q34: =IF(W34="","",IF(WEEKDAY(W34)=1,W34+1,W34)) -> 46263 | R34: =IF(Q34="","",IF(AND(N(K34)>=3,G34<>"Perdido"),"Mover para Perdido",IF(Q34<TODAY(),"Atrasado",IF(Q34=TODAY(),"Hoje","No prazo")))) -> Atrasado | S34: Só pode sábado | V34: vai pensar | W34: =IF(G34="","",IF(OR(G34="Novo contato",G34="Em conversa"),IF(J34="",TODAY(),J34+1),IF(G34="Avaliação marcada",IF(L34="",TODAY(),L34-1),IF(G34="Proposta enviada",IF(J34="",TODAY(),J34+2),IF(G34="Fechou pacote",IF(J34="",TODAY(),J34+7),IF(G34="Em tratamento",IF(M34="",TODAY(),IF(TODAY()<=M34+1,M34+1,EDATE(M34,6)-30)),IF(G34="Pós-venda",IF(J34="",TODAY(),J34+7),IF(G34="Perdido",IF(J34="",TODAY(),J34+60),"")))))))) -> 46263
A35: Cliente 034 | B35: (15) 99999-2736 | C35: Instagram | E35: Limpeza de pele | F35: =IF(OR(E35="",E35="A completar",E35="Ainda não sabe"),"",IF(OR(E35="Limpeza de pele",E35="Peeling de diamante",E35="Microagulhamento"),"Rosto","Corpo")) -> Rosto | G35: Novo contato | I35: Nina | J35: 46229 | K35: 0 | P35: =IF(M35="","",EDATE(M35,6)) | Q35: =IF(W35="","",IF(WEEKDAY(W35)=1,W35+1,W35)) -> 46230 | R35: =IF(Q35="","",IF(AND(N(K35)>=3,G35<>"Perdido"),"Mover para Perdido",IF(Q35<TODAY(),"Atrasado",IF(Q35=TODAY(),"Hoje","No prazo")))) -> Atrasado | S35: Quer parcelar | V35: (em branco) | W35: =IF(G35="","",IF(OR(G35="Novo contato",G35="Em conversa"),IF(J35="",TODAY(),J35+1),IF(G35="Avaliação marcada",IF(L35="",TODAY(),L35-1),IF(G35="Proposta enviada",IF(J35="",TODAY(),J35+2),IF(G35="Fechou pacote",IF(J35="",TODAY(),J35+7),IF(G35="Em tratamento",IF(M35="",TODAY(),IF(TODAY()<=M35+1,M35+1,EDATE(M35,6)-30)),IF(G35="Pós-venda",IF(J35="",TODAY(),J35+7),IF(G35="Perdido",IF(J35="",TODAY(),J35+60),"")))))))) -> 46230
A36: Cliente 035 | B36: (15) 99999-6952 | C36: Instagram | E36: Massagem modeladora | F36: =IF(OR(E36="",E36="A completar",E36="Ainda não sabe"),"",IF(OR(E36="Limpeza de pele",E36="Peeling de diamante",E36="Microagulhamento"),"Rosto","Corpo")) -> Corpo | G36: Em conversa | I36: Nina | J36: 46234 | K36: 0 | P36: =IF(M36="","",EDATE(M36,6)) | Q36: =IF(W36="","",IF(WEEKDAY(W36)=1,W36+1,W36)) -> 46235 | R36: =IF(Q36="","",IF(AND(N(K36)>=3,G36<>"Perdido"),"Mover para Perdido",IF(Q36<TODAY(),"Atrasado",IF(Q36=TODAY(),"Hoje","No prazo")))) -> Atrasado | V36: pediu preço | W36: =IF(G36="","",IF(OR(G36="Novo contato",G36="Em conversa"),IF(J36="",TODAY(),J36+1),IF(G36="Avaliação marcada",IF(L36="",TODAY(),L36-1),IF(G36="Proposta enviada",IF(J36="",TODAY(),J36+2),IF(G36="Fechou pacote",IF(J36="",TODAY(),J36+7),IF(G36="Em tratamento",IF(M36="",TODAY(),IF(TODAY()<=M36+1,M36+1,EDATE(M36,6)-30)),IF(G36="Pós-venda",IF(J36="",TODAY(),J36+7),IF(G36="Perdido",IF(J36="",TODAY(),J36+60),"")))))))) -> 46235
A37: Cliente 036 | B37: (15) 99999-6351 | C37: Instagram (anúncio) | E37: Microagulhamento | F37: =IF(OR(E37="",E37="A completar",E37="Ainda não sabe"),"",IF(OR(E37="Limpeza de pele",E37="Peeling de diamante",E37="Microagulhamento"),"Rosto","Corpo")) -> Rosto | G37: Proposta enviada | I37: Nina | J37: 46235 | K37: 0 | P37: =IF(M37="","",EDATE(M37,6)) | Q37: =IF(W37="","",IF(WEEKDAY(W37)=1,W37+1,W37)) -> 46237 | R37: =IF(Q37="","",IF(AND(N(K37)>=3,G37<>"Perdido"),"Mover para Perdido",IF(Q37<TODAY(),"Atrasado",IF(Q37=TODAY(),"Hoje","No prazo")))) -> Atrasado | V37: fez avaliação | W37: =IF(G37="","",IF(OR(G37="Novo contato",G37="Em conversa"),IF(J37="",TODAY(),J37+1),IF(G37="Avaliação marcada",IF(L37="",TODAY(),L37-1),IF(G37="Proposta enviada",IF(J37="",TODAY(),J37+2),IF(G37="Fechou pacote",IF(J37="",TODAY(),J37+7),IF(G37="Em tratamento",IF(M37="",TODAY(),IF(TODAY()<=M37+1,M37+1,EDATE(M37,6)-30)),IF(G37="Pós-venda",IF(J37="",TODAY(),J37+7),IF(G37="Perdido",IF(J37="",TODAY(),J37+60),"")))))))) -> 46237
A38: Cliente 037 | B38: (15) 99999-0060 | C38: Instagram | E38: Massagem modeladora | F38: =IF(OR(E38="",E38="A completar",E38="Ainda não sabe"),"",IF(OR(E38="Limpeza de pele",E38="Peeling de diamante",E38="Microagulhamento"),"Rosto","Corpo")) -> Corpo | G38: Proposta enviada | I38: Nina | J38: 46242 | K38: 0 | P38: =IF(M38="","",EDATE(M38,6)) | Q38: =IF(W38="","",IF(WEEKDAY(W38)=1,W38+1,W38)) -> 46244 | R38: =IF(Q38="","",IF(AND(N(K38)>=3,G38<>"Perdido"),"Mover para Perdido",IF(Q38<TODAY(),"Atrasado",IF(Q38=TODAY(),"Hoje","No prazo")))) -> Atrasado | S38: Só pode sábado | V38: fez avaliação | W38: =IF(G38="","",IF(OR(G38="Novo contato",G38="Em conversa"),IF(J38="",TODAY(),J38+1),IF(G38="Avaliação marcada",IF(L38="",TODAY(),L38-1),IF(G38="Proposta enviada",IF(J38="",TODAY(),J38+2),IF(G38="Fechou pacote",IF(J38="",TODAY(),J38+7),IF(G38="Em tratamento",IF(M38="",TODAY(),IF(TODAY()<=M38+1,M38+1,EDATE(M38,6)-30)),IF(G38="Pós-venda",IF(J38="",TODAY(),J38+7),IF(G38="Perdido",IF(J38="",TODAY(),J38+60),"")))))))) -> 46244
A39: Cliente 038 | B39: (15) 99999-4051 | C39: Google | E39: Microagulhamento | F39: =IF(OR(E39="",E39="A completar",E39="Ainda não sabe"),"",IF(OR(E39="Limpeza de pele",E39="Peeling de diamante",E39="Microagulhamento"),"Rosto","Corpo")) -> Rosto | G39: Avaliação marcada | I39: Nina | J39: 46251 | K39: 0 | P39: =IF(M39="","",EDATE(M39,6)) | Q39: =IF(W39="","",IF(WEEKDAY(W39)=1,W39+1,W39)) -> 46309 | R39: =IF(Q39="","",IF(AND(N(K39)>=3,G39<>"Perdido"),"Mover para Perdido",IF(Q39<TODAY(),"Atrasado",IF(Q39=TODAY(),"Hoje","No prazo")))) -> Hoje | S39: Já fez em outra clínica | V39: avaliação? | W39: =IF(G39="","",IF(OR(G39="Novo contato",G39="Em conversa"),IF(J39="",TODAY(),J39+1),IF(G39="Avaliação marcada",IF(L39="",TODAY(),L39-1),IF(G39="Proposta enviada",IF(J39="",TODAY(),J39+2),IF(G39="Fechou pacote",IF(J39="",TODAY(),J39+7),IF(G39="Em tratamento",IF(M39="",TODAY(),IF(TODAY()<=M39+1,M39+1,EDATE(M39,6)-30)),IF(G39="Pós-venda",IF(J39="",TODAY(),J39+7),IF(G39="Perdido",IF(J39="",TODAY(),J39+60),"")))))))) -> 46309
A40: Cliente 039 | B40: (15) 99999-7554 | C40: Instagram (anúncio) | E40: Depilação a laser | F40: =IF(OR(E40="",E40="A completar",E40="Ainda não sabe"),"",IF(OR(E40="Limpeza de pele",E40="Peeling de diamante",E40="Microagulhamento"),"Rosto","Corpo")) -> Corpo | G40: Em conversa | I40: Nina | J40: 46275 | K40: 1 | P40: =IF(M40="","",EDATE(M40,6)) | Q40: =IF(W40="","",IF(WEEKDAY(W40)=1,W40+1,W40)) -> 46276 | R40: =IF(Q40="","",IF(AND(N(K40)>=3,G40<>"Perdido"),"Mover para Perdido",IF(Q40<TODAY(),"Atrasado",IF(Q40=TODAY(),"Hoje","No prazo")))) -> Atrasado | S40: Já fez em outra clínica | V40: sumiu | W40: =IF(G40="","",IF(OR(G40="Novo contato",G40="Em conversa"),IF(J40="",TODAY(),J40+1),IF(G40="Avaliação marcada",IF(L40="",TODAY(),L40-1),IF(G40="Proposta enviada",IF(J40="",TODAY(),J40+2),IF(G40="Fechou pacote",IF(J40="",TODAY(),J40+7),IF(G40="Em tratamento",IF(M40="",TODAY(),IF(TODAY()<=M40+1,M40+1,EDATE(M40,6)-30)),IF(G40="Pós-venda",IF(J40="",TODAY(),J40+7),IF(G40="Perdido",IF(J40="",TODAY(),J40+60),"")))))))) -> 46276
...

Sheet Etapas do funil
A1: Etapas do funil
A2: As colunas do quadro, na ordem do caminho da cliente.
A4: # | B4: Etapa | C4: Quando o cartão entra aqui | D4: Quem move para a próxima | E4: Situações da planilha antiga que vieram para cá
A5: 1 | B5: Novo contato | C5: A cliente mandou a primeira mensagem (WhatsApp, Instagram, Google, indicação, fachada). | D5: Nina | E5: (em branco)
A6: 2 | B6: Em conversa | C6: A Nina já respondeu, a cliente pediu preço ou tirou dúvida, mas ainda não marcou a avaliação. | D6: Nina | E6: pediu preço · ligar de novo · não respondeu · sumiu
A7: 3 | B7: Avaliação marcada | C7: A avaliação gratuita está com dia e hora marcados. | D7: Nina ou Otávio | E7: marcou avaliação · remarcar · avaliação?
A8: 4 | B8: Proposta enviada | C8: A cliente fez a avaliação, o Otávio montou a proposta e a Nina enviou no mesmo dia. | D8: Nina | E8: fez avaliação · achou caro · vai pensar
A9: 5 | B9: Fechou pacote | C9: A cliente pagou o pacote e falta fazer a 1ª sessão. | D9: Quem registrar a 1ª sessão | E9: fechou pacote
A10: 6 | B10: Em tratamento | C10: A 1ª sessão foi feita. A planilha mostra a validade do pacote. | D10: Quem registrar a última sessão
A11: 7 | B11: Pós-venda | C11: O pacote terminou. Pedir opinião e indicação e oferecer o próximo tratamento. | D11: Nina
A12: — | B12: Perdido | C12: A cliente disse não ou não respondeu depois de 3 tentativas. Escolher o motivo é obrigatório. Pode voltar para Em conversa se a cliente reaparecer. | D12: Nina
B13: REGRA | C13: O cartão não vai para Fechou pacote sem a avaliação feita. A clínica só vende pacote depois da avaliação.

Sheet Dados do cliente
A1: Dados de cada cliente
A2: O que cada coluna da aba Clientes significa. ★ = obrigatório.
A4: Campo | B4: Grupo | C4: Como preenche | D4: Observação
A5: Nome ★ | B5: Identificação | C5: Texto
A6: Telefone / WhatsApp ★ | B6: Identificação | C6: Número com DDD | D6: Confira se a cliente já não está cadastrada.
A7: Origem ★ | B7: De onde veio | C7: Menu | D7: Instagram · Instagram (anúncio) · Google · Indicação · Fachada · Outro
A8: Indicada por | B8: De onde veio | C8: Texto | D8: Só quando a origem é Indicação.
A9: Interesse ★ | B9: De onde veio | C9: Menu | D9: Tratamentos da tabela de preços ou "Ainda não sabe".
A10: Área | B10: De onde veio | C10: Automático | D10: Rosto ou Corpo, a partir do interesse.
A11: Etapa ★ | B11: Andamento | C11: Menu | D11: A coluna do quadro em que a cliente está.
A12: Etiqueta da proposta | B12: Andamento | C12: Menu | D12: achou caro · vai pensar · quer parcelar. Só na etapa Proposta enviada.
A13: Responsável ★ | B13: Andamento | C13: Menu | D13: Nina por padrão.
A14: Último contato ★ | B14: Andamento | C14: Data | D14: Atualize sempre que falar com a cliente.
A15: Tentativas sem resposta | B15: Andamento | C15: Número de 0 a 3 | D15: Volta para 0 quando a cliente responde.
A16: Data da avaliação | B16: Avaliação | C16: Data | D16: Dia marcado da avaliação gratuita.
A17: Data da 1ª sessão | B17: Pacote | C17: Data | D17: Começa a contar a validade de 6 meses.
... A26: Ainda não estão na planilha | B26: Próxima versão | C26: — | D26: Valor da proposta, forma de pagamento, data de envio da proposta, profissional, autorização de foto (sim/não e data) e exceção aprovada pela Paula. Estão descritos no documento do produto.

Sheet Regras de retorno
A1: Regras de retorno
A2: Quando a Nina volta a falar com a cliente.
A4: Situação | B4: Quando | C4: De onde vem a regra | D4: A planilha calcula sozinha?
A5: Contato novo parou de responder | B5: 1 dia depois do último contato | C5: Roteiro do WhatsApp | D5: Sim
A6: Fez a avaliação e não respondeu à proposta | B6: 2 dias depois do último contato | C6: Roteiro do WhatsApp | D6: Sim
A7: Comprou o pacote | B7: Pós-venda 7 dias depois | C7: Roteiro do WhatsApp | D7: Sim
A8: Contato sem data | B8: No mesmo dia | C8: Roteiro do WhatsApp | D8: Sim
A9: Fez a 1ª sessão | B9: 1 dia depois da 1ª sessão | C9: Oferta e preços (prazo sugerido) | D9: Sim
A10: Fez criolipólise | B10: Marcar retorno com o Otávio aos 53 dias (consulta aos 60 dias) | C10: Oferta e preços | D10: Não: anotar na observação
A11: Cliente não responde | B11: Até 3 tentativas. Na 3ª, mover para Perdido | C11: Definido neste projeto | D11: Sim (avisa)
A12: Contato perdido | B12: Uma nova tentativa 60 dias depois | C12: Sugestão | D12: Sim
A13: Avaliação marcada | B13: Lembrete na véspera | C13: Sugestão | D13: Sim
A14: Faltou ou pediu para remarcar a avaliação | B14: No mesmo dia | C14: Sugestão | D14: Sim (quando não há data de avaliação)
A15: Etiqueta achou caro ou vai pensar | B15: 2 dias. Lembrar: 6x sem juros ou 10% à vista no Pix | C15: Oferta e preços | D15: Sim
... A19: Horário | B19: Seg a sex, 9h às 19h · sáb, 9h às 13h. Domingo passa para segunda | C19: Oferta e preços | D19: Sim (domingo)

Sheet Regras da clínica
A1: Regras que ninguém quebra
A2: E o que o CRM faz para proteger cada uma.
A4: Regra | B4: O que o CRM faz
A5: Só vende pacote depois da avaliação. | B5: O cartão não vai para Fechou pacote sem avaliação feita.
A6: Desconto máximo de 10%, só à vista no Pix. | B6: A forma de pagamento só oferece Pix com 10%, débito ou crédito em até 6x.
A7: Nunca prometer resultado em centímetro ou em quilo. | B7: A etiqueta "Perguntou do resultado" traz o lembrete.
A8: Foto de antes e depois só com autorização por escrito. | B8: A etiqueta "Pediu foto de antes e depois" traz o lembrete.
A9: Proposta enviada no mesmo dia da avaliação. | B9: A Nina confere na lista de retornos do dia.
A10: Exceções só com a Paula, sempre por escrito. | B10: Registrar na observação, com a data.

Sheet Quem usa
A1: Quem usa o CRM
A4: Pessoa | B4: Papel na clínica | C4: O que faz no CRM
A5: Nina | B5: Recepção e WhatsApp | C5: Cadastra cada contato, move as clientes de etapa, registra cada conversa, trabalha os retornos do dia e envia as propostas.
A6: Otávio | B6: Biomédico esteta: avaliações, criolipólise e laser | C6: Registra a avaliação feita, o tratamento indicado e a proposta. Acompanha o retorno de 60 dias da criolipólise.
A7: Camila | B7: Terapeuta corporal: drenagem e modeladora | C7: Marca as sessões feitas das clientes em tratamento corporal.
A8: Paula | B8: Fundadora: define preços e exceções | C8: Acompanha o Painel e aprova as exceções, por escrito.

Sheet Pontos a confirmar
A1: Pontos para a Paula confirmar
A2: Regras sugeridas: os documentos da clínica não dizem o prazo.
A4: Pergunta | B4: Sugestão usada na planilha | C4: Resposta da Paula
A5: Retorno depois da 1ª sessão | B5: 1 dia depois
A6: Lembrete na véspera da avaliação | B6: Sim
A7: Nova tentativa com quem foi para Perdido | B7: 60 dias depois, uma única vez
A8: Oferecer o próximo tratamento depois do fim do pacote | B8: 30 dias depois
A9: Otávio e Camila podem mudar a etapa da cliente? | B9: Só registram avaliações e sessões

Sheet Listas
A1: Listas dos menus
A2: Para incluir uma opção nova, escreva no fim da coluna certa.
A4: Etapa | B4: Origem | C4: Interesse | D4: Etiqueta da proposta | E4: Responsável | F4: Motivo da perda | G4: Pagamento
A5: Novo contato | B5: Instagram | C5: Limpeza de pele | D5: achou caro | E5: Nina | F5: Achou caro | G5: Pix à vista (10% de desconto)
A6: Em conversa | B6: Instagram (anúncio) | C6: Peeling de diamante | D6: vai pensar | E6: Otávio | F6: Não respondeu (3 tentativas) | G6: Débito
A7: Avaliação marcada | B7: Google | C7: Microagulhamento | D7: quer parcelar | E7: Camila | F7: Fechou em outra clínica | G7: Crédito em até 6x
A8: Proposta enviada | B8: Indicação | C8: Drenagem linfática | E8: Paula | F8: Horário não serve
A9: Fechou pacote | B9: Fachada | C9: Massagem modeladora | F9: Desistiu do tratamento
A10: Em tratamento | B10: Outro | C10: Criolipólise | F10: Outro
A11: Pós-venda | B11: A completar | C11: Depilação a laser
A12: Perdido | C12: Ainda não sabe
C13: A completar
